<?xml version='1.0'?>
<sdf version='1.3'>
  <model name="hal">
    <static>false</static>
    
    <link name='chassis'>
      <inertial>
        <mass>100</mass>
        <pose>0 0 0 0 0 0</pose>
        <inertia>
          <ixx>10</ixx>
          <ixy>0</ixy>
          <ixz>0</ixz>
          <iyy>10</iyy>
          <iyz>0</iyz>
          <izz>10</izz>
        </inertia>
      </inertial>
      
      <collision name='base1_c'>
        <pose> -0.2413 0 0.29685 0 0 0</pose>
        <geometry>
          <box>
            <size>0.6858 0.4318 0.3937</size>
          </box>
        </geometry>
      </collision>

      <visual name='base1_v'>
        <pose> -0.2413 0 0.29685 0 0 0</pose>
        <geometry>
          <box>
            <size>0.6858 0.4318 0.3937</size>
          </box>
        </geometry>
      </visual>

      <collision name='base2_c'>
        <pose> -0.2413 0 0.6588 0 0 0</pose>
        <geometry>
          <box>
            <size>0.6858 0.6096 0.3302</size>
          </box>
        </geometry>
      </collision>

      <visual name='base2_v'>
        <pose> -0.2413 0 0.6588 0 0 0</pose>
        <geometry>
          <box>
            <size>0.6858 0.6096 0.3302</size>
          </box>
        </geometry>
      </visual>

      <collision name='base3_c'>
        <pose> 0.0889 0 1.10965 0 0 0</pose>
        <geometry>
          <box>
            <size>0.4826 0.6096 0.5715</size>
          </box>
        </geometry>
      </collision>

      <visual name='base3_v'>
        <pose> 0.0889 0 1.10965 0 0 0</pose>
        <geometry>
          <box>
            <size>0.4826 0.6096 0.5715</size>
          </box>
        </geometry>
      </visual>
      
      
      
      <collision name='left_caster_c'>
        <pose>-0.4318 0.2286 0.1 0 0 0</pose>
        <geometry>
          <sphere>
            <radius>0.1</radius>
          </sphere>
        </geometry>

        <surface>
          <friction>
            <ode>
              <mu>0</mu>
              <mu2>0</mu2>
              <slip1>1.0</slip1>
              <slip2>1.0</slip2>
            </ode>
          </friction>
        </surface>
      </collision>
  
      <visual name='left_caster_v'>
        <pose>-0.4318 0.2286 0.1 0 0 0</pose>
        <geometry>
          <sphere>
            <radius>0.1</radius>
          </sphere>
        </geometry>
      </visual>
      
      <collision name='right_caster_c'>
        <pose>-0.4318 -0.2286 0.1 0 0 0</pose>
        <geometry>
          <sphere>
            <radius>0.1</radius>
          </sphere>
        </geometry>

        <surface>
          <friction>
            <ode>
              <mu>0</mu>
              <mu2>0</mu2>
              <slip1>1.0</slip1>
              <slip2>1.0</slip2>
            </ode>
          </friction>
        </surface>
      </collision>
  
      <visual name='right_caster_v'>
        <pose>-0.4318 -0.2286 0.1 0 0 0</pose>
        <geometry>
          <sphere>
            <radius>0.1</radius>
          </sphere>
        </geometry>
      </visual>
    </link>
      
    <link name="left_wheel">
      <pose>0.0 0.254 0.127 0 1.5707 1.5707</pose>
      <collision name="collision">
        <geometry>
          <cylinder>
            <radius>0.127</radius>
            <length>0.0762</length>
          </cylinder>
        </geometry>
      </collision>
      
      <visual name="visual">
        <geometry>
          <cylinder>
            <radius>0.127</radius>
            <length>0.0762</length>
          </cylinder>
        </geometry>
      </visual>
    </link>
    
    <link name="right_wheel">
      <pose>0.0 -0.254 0.127 0 1.5707 1.5707</pose>
      <collision name="collision">
        <geometry>
          <cylinder>
            <radius>0.127</radius>
            <length>0.0762</length>
          </cylinder>
        </geometry>
      </collision>
      
      <visual name="visual">
        <geometry>
          <cylinder>
            <radius>0.127</radius>
            <length>0.0762</length>
          </cylinder>
        </geometry>
      </visual>
    </link>
    
    <joint type="revolute" name="left_wheel_hinge">
      <pose>0 0 -0.03 0 0 0</pose>
      <child>left_wheel</child>
      <parent>chassis</parent>
      <axis>
        <xyz>0 1 0</xyz>
      </axis>
    </joint>
    
    <joint type="revolute" name="right_wheel_hinge">
      <pose>0 0 0.03 0 0 0</pose>
      <child>right_wheel</child>
      <parent>chassis</parent>
      <axis>
        <xyz>0 1 0</xyz>
      </axis>
    </joint>
    
 
    <link name="left_camera_link">
      <pose>0.3302 0.05 1.3854 0 1.047 0</pose>
      <inertial>
        <mass>0.001</mass>
      </inertial>
      <collision name="left_camera_c">
        <geometry>
          <box>
            <size>0.05 0.05 0.05</size>
          </box>
        </geometry>
      </collision>
      <visual name="left_camera_v">
        <geometry>
          <box>
            <size>0.05 0.05 0.05</size>
          </box>
        </geometry>
      </visual>
      <sensor name="left_camera" type="camera">
        <camera>
          <horizontal_fov>0.9953</horizontal_fov>
          <image>
            <width>640</width>
            <height>480</height>
          </image>
          <clip>
            <near>0.1</near>
            <far>100</far>
          </clip>
        </camera>
        <always_on>1</always_on>
        <update_rate>30</update_rate>
        <visualize>true</visualize>
      </sensor>
    </link>
    
 
    <link name="right_camera_link">
      <pose>0.3302 -0.05 1.3854 0 1.047 0</pose>
      <inertial>
        <mass>0.001</mass>
      </inertial>
      <collision name="right_camera_c">
        <geometry>
          <box>
            <size>0.05 0.05 0.05</size>
          </box>
        </geometry>
      </collision>
      <visual name="right_camera_v">
        <geometry>
          <box>
            <size>0.05 0.05 0.05</size>
          </box>
        </geometry>
      </visual>
      <sensor name="right_camera" type="camera">
        <camera>
          <horizontal_fov>0.9953</horizontal_fov>
          <image>
            <width>640</width>
            <height>480</height>
          </image>
          <clip>
            <near>0.1</near>
            <far>100</far>
          </clip>
        </camera>
        <always_on>1</always_on>
        <update_rate>30</update_rate>
        <visualize>true</visualize>
      </sensor>
    </link>
    
    <joint name="left_camera_joint" type="revolute">
      <child>left_camera_link</child>
      <parent>chassis</parent>
      <axis>
        <xyz>0 1 0</xyz>
        <limit>
          <upper>0</upper>
          <lower>0</lower>
        </limit>
      </axis>
    </joint>
    
    <joint name="right_camera_joint" type="revolute">
      <child>right_camera_link</child>
      <parent>chassis</parent>
      <axis>
        <xyz>0 1 0</xyz>
        <limit>
          <upper>0</upper>
          <lower>0</lower>
        </limit>
      </axis>
    </joint>
  </model>
</sdf>
