<?xml version='1.0'?>
<robot name="hal" xmlns:body="http://playerstage.sourceforge.net/gazebo/xmlschema/#body" xmlns:controller="http://playerstage.sourceforge.net/gazebo/xmlschema/#controller" xmlns:geom="http://playerstage.sourceforge.net/gazebo/xmlschema/#geom" xmlns:sensor="http://playerstage.sourceforge.net/gazebo/xmlschema/#sensor" xmlns:xacro="http://ros.org/wiki/xacro">
    <link name='base_link'>
      <inertial>
        <mass value="100" />
        <origin xyz="-0.2413 0 0.29685" />
        <inertia ixx="5" ixy="0.0" ixz="0.0" iyy="5" iyz="0.0" izz="5" />
      </inertial>
      
      <collision name='base1_c'>
        <origin xyz="-0.2413 0 0.29685" rpy="0 0 0"/>
        <geometry>
          <box size="0.6858 0.4318 0.3937"/>
        </geometry>
      </collision>

      <visual name='base1_v'>
        <origin xyz="-0.2413 0 0.29685" rpy="0 0 0"/>
        <geometry>
          <box size="0.6858 0.4318 0.3937"/>
        </geometry>
        <material name="grey">
          <color rgba="0.3 0.3 0.3 1"/>
        </material>
      </visual>

      <collision name='base2_c'>
        <origin xyz="-0.2413 0 0.6588" rpy="0 0 0"/>
        <geometry>
          <box size="0.6858 0.6096 0.3302"/>
        </geometry>
      </collision>

      <!--<visual name='base2_v'>
        <origin xyz="-0.2413 0 0.6588" rpy="0 0 0"/>
        <geometry>
          <box size="0.6858 0.6096 0.3302"/>
        </geometry>
      </visual>-->

      <!--<collision name='base3_c'>
        <origin xyz="0.0889 0 1.10965" rpy="0 0 0"/>
        <geometry>
          <box size="0.4826 0.6096 0.5715"/>
        </geometry>
      </collision>

      <visual name='base3_v'>
        <origin xyz="0.0889 0 1.10965" rpy="0 0 0"/>
        <geometry>
          <box size="0.4826 0.6096 0.5715"/>
        </geometry>
      </visual>-->
    </link>
    
    <link name="left_caster">
      <inertial>
        <mass value="0.001"/>
        <origin xyz="0 0 0"/>
        <inertia ixx="0.001" ixy="0" ixz="0" iyy="0.001" iyz="0" izz="0.001"/>
      </inertial>
      
      <collision name='left_caster_c'>
        <geometry>
          <sphere radius="0.1"/>
        </geometry>
      </collision>
  
      <visual name='left_caster_v'>
        <geometry>
          <sphere radius="0.1"/>
        </geometry>
      </visual>
    </link>
    
    <link name="right_caster">
      <inertial>
        <mass value="0.001"/>
        <origin xyz="0 0 0"/>
        <inertia ixx="0.001" ixy="0" ixz="0" iyy="0.001" iyz="0" izz="0.001"/>
      </inertial>
      
      <collision name='right_caster_c'>
        <geometry>
          <sphere radius="0.1"/>
        </geometry>
      </collision>
  
      <visual name='right_caster_v'>
        <geometry>
          <sphere radius="0.1"/>
        </geometry>
      </visual>
    </link>
    
    <joint name="left_caster_joint" type="fixed">
        <origin xyz="-0.4318 0.2286 0.1" rpy="0 0 0"/>
      <parent link="base_link"/>
      <child link="left_caster"/>
    </joint>
    
    <joint name="right_caster_joint" type="fixed">
        <origin xyz="-0.4318 -0.2286 0.1" rpy="0 0 0"/>
      <parent link="base_link"/>
      <child link="right_caster"/>
    </joint>
      
    <link name="left_wheel">
      <inertial>
        <mass value="0.1"/>
        <origin xyz="0 0 0"/>
        <inertia ixx="0.1" ixy="0" ixz="0" iyy="0.1" iyz="0" izz="0.1"/>
      </inertial>
      
      <collision name="collision">
        <origin xyz="0 0 0" rpy="0 1.5707 1.5707"/>
        <geometry>
          <cylinder radius="0.127" length="0.0762"/>
        </geometry>
      </collision>
      
      <visual name="visual">
        <origin xyz="0 0 0" rpy="0 1.5707 1.5707"/>
        <geometry>
          <cylinder radius="0.127" length="0.0762"/>
        </geometry>
      </visual>
    </link>
    
    <link name="right_wheel">
      <inertial>
        <mass value="0.1"/>
        <origin xyz="0 0 0"/>
        <inertia ixx="0.1" ixy="0" ixz="0" iyy="0.1" iyz="0" izz="0.1"/>
      </inertial>
    
      <collision name="collision">
        <origin xyz="0 0 0" rpy="0 1.5707 1.5707"/>
        <geometry>
          <cylinder radius="0.127" length="0.0762"/>
        </geometry>
      </collision>
      
      <visual name="visual">
        <origin xyz="0 0 0" rpy="0 1.5707 1.5707"/>
        <geometry>
          <cylinder radius="0.127" length="0.0762"/>
        </geometry>
      </visual>
    </link>
    
    <joint type="revolute" name="left_wheel_joint">
      <origin xyz="0.0 0.254 0.127" rpy="0 0 0"/>
      <child link="left_wheel"/>
      <parent link="base_link"/>
      <axis xyz="0 1 0"/>
      <dynamics damping="0" friction="0" />
      <limit effort="3000" velocity="3000" lower="-1e+20" upper="1e+20" />
      <safety_controller k_position="100" k_velocity="100" soft_lower_limit="-3000" soft_upper_limit="3000" />
    </joint>
    <transmission name="right_wheel_trans" type="pr2_mechanism_model/SimpleTransmission">
      <actuator name="right_wheel_motor"/>
      <joint name="left_wheel_joint"/>
      <mechanicalReduction>1.0</mechanicalReduction>
    </transmission>
    
    <joint type="revolute" name="right_wheel_joint">
      <origin xyz="0.0 -0.254 0.127" rpy="0 0 0"/>
      <child link="right_wheel"/>
      <parent link="base_link"/>
      <axis xyz="0 1 0"/>
      <dynamics damping="0" friction="0" />
      <limit effort="3000" velocity="3000" lower="-1e+20" upper="1e+20" />
      <safety_controller k_position="100" k_velocity="100" soft_lower_limit="-3000" soft_upper_limit="3000" />
    </joint>
    <transmission name="right_wheel_trans" type="pr2_mechanism_model/SimpleTransmission">
      <actuator name="right_wheel_motor"/>
      <joint name="right_wheel_joint"/>
      <mechanicalReduction>1.0</mechanicalReduction>
    </transmission>
 
    <link name="left_camera_link">
      <inertial>
        <mass value="0.0001"/>
        <origin xyz="0 0 0"/>
        <inertia ixx="0.000001" ixy="0" ixz="0" iyy="0.000001" iyz="0" izz="0.000001"/>
      </inertial>
      <collision name="left_camera_c">
        <geometry>
          <box size="0.05 0.05 0.05"/>
        </geometry>
      </collision>
      <visual name="visual">
        <geometry>
          <box size="0.05 0.05 0.05"/>
        </geometry>
      </visual>
    </link>
 
    <link name="left_camera_optical_frame">
      <inertial>
        <mass value="0.0001"/>
        <origin xyz="0 0 0"/>
        <inertia ixx="0.000001" ixy="0" ixz="0" iyy="0.000001" iyz="0" izz="0.000001"/>
      </inertial>
      <collision name="left_camera_c">
        <geometry>
          <box size="0.0001 0.0001 0.0001"/>
        </geometry>
      </collision>
      <visual name="visual">
        <geometry>
          <box size="0.0001 0.0001 0.0001"/>
        </geometry>
      </visual>
    </link>
    
    <!-- x=0.19
    y=0.21
    z=0.73
    49.3 pitch, 45 yaw -->
    <joint name="left_camera_joint" type="fixed">
   
      <!-- <origin xyz="0.2667 0.0508 1.332" rpy="0 0.785398163 0"/> -->
      <origin xyz="0.21 0.17 0.73" rpy="0 0.888372589 0.785398163"/>
      <!-- <origin xyz="0.1524 0.1524 0.7112" rpy="0 0.785 0.9"/> -->
      <parent link="base_link"/>
      <child link="left_camera_link"/>
    </joint>
    
    <joint name="left_camera_optical_joint" type="fixed">
        <origin xyz="0 0 0 " rpy="-1.57 0 -1.57"/>
      <parent link="left_camera_link"/>
      <child link="left_camera_optical_frame"/>
    </joint>
 
    <link name="right_camera_link">
      <inertial>
        <mass value="0.0001"/>
        <origin xyz="0 0 0"/>
        <inertia ixx="0.000001" ixy="0" ixz="0" iyy="0.000001" iyz="0" izz="0.000001"/>
      </inertial>
      <collision name="right_camera_c">
        <geometry>
          <box size="0.05 0.05 0.05"/>
        </geometry>
      </collision>
      <visual name="visual">
        <geometry>
          <box size="0.05 0.05 0.05"/>
        </geometry>
      </visual>
    </link>
    
    <link name="right_camera_optical_frame">
      <inertial>
        <mass value="0.0001"/>
        <origin xyz="0 0 0"/>
        <inertia ixx="0.000001" ixy="0" ixz="0" iyy="0.000001" iyz="0" izz="0.000001"/>
      </inertial>
      <collision name="right_camera_c">
        <geometry>
          <box size="0.0001 0.0001 0.0001"/>
        </geometry>
      </collision>
      <visual name="visual">
        <geometry>
          <box size="0.0001 0.0001 0.0001"/>
        </geometry>
      </visual>
    </link>
    

    <!-- x=0.17
    y=-0.215
    z=0.73
    57.45 pitch 45 yaw -->
    <joint name="right_camera_joint" type="fixed">
      <!-- <origin xyz="0.2667 -0.05715 1.332" rpy="0 0.785398163 0"/> -->
      <origin xyz="0.21 -0.22 0.73" rpy="0 1.03672558 -0.785398163"/>
      <parent link="base_link"/>
      <child link="right_camera_link"/>
    </joint>
    
    <joint name="right_camera_optical_joint" type="fixed">
        <origin xyz="0 0 0 " rpy="-1.57 0 -1.57"/>
      <parent link="right_camera_link"/>
      <child link="right_camera_optical_frame"/>
    </joint>
    
    <gazebo reference="left_camera_link">
      <sensor type="camera" name="left_camera">
        <update_rate>30.0</update_rate>
        <camera name="left_camera">
          <horizontal_fov>2.0943951</horizontal_fov>
          <image>
            <width>1280</width>
            <height>720</height>
            <format>R8G8B8</format>
          </image>
          <clip>
            <near>0.02</near>
            <far>300</far>
          </clip>
        </camera>
        <plugin name="camera_controller" filename="libgazebo_ros_camera.so">
          <alwaysOn>true</alwaysOn>
          <updateRate>30.0</updateRate>
          <cameraName>left_camera</cameraName>
          <imageTopicName>image_raw</imageTopicName>
          <cameraInfoTopicName>camera_info</cameraInfoTopicName>
          <frameName>left_camera_optical_frame</frameName>
          <hackBaseline>0.07</hackBaseline>
          <distortionK1>0.0</distortionK1>
          <distortionK2>0.0</distortionK2>
          <distortionK3>0.0</distortionK3>
          <distortionT1>0.0</distortionT1>
          <distortionT2>0.0</distortionT2>
        </plugin>
      </sensor>
      <material>Gazebo/Black</material>
    </gazebo> 
      
      
    <gazebo reference="right_camera_link">
      <sensor type="camera" name="right_camera">
        <update_rate>30.0</update_rate>
        <camera name="right_camera">
          <horizontal_fov>2.0943951</horizontal_fov>
          <image>
            <width>1280</width>
            <height>720</height>
            <format>R8G8B8</format>
          </image>
          <clip>
            <near>0.02</near>
            <far>300</far>
          </clip>
        </camera>
        <plugin name="camera_controller" filename="libgazebo_ros_camera.so">
          <alwaysOn>true</alwaysOn>
          <updateRate>30.0</updateRate>
          <cameraName>right_camera</cameraName>
          <imageTopicName>image_raw</imageTopicName>
          <cameraInfoTopicName>camera_info</cameraInfoTopicName>
          <frameName>right_camera_optical_frame</frameName>
          <hackBaseline>0.07</hackBaseline>
          <distortionK1>0.0</distortionK1>
          <distortionK2>0.0</distortionK2>
          <distortionK3>0.0</distortionK3>
          <distortionT1>0.0</distortionT1>
          <distortionT2>0.0</distortionT2>
        </plugin>
      </sensor>
      <material>Gazebo/Black</material>
    </gazebo>
    
    <gazebo>
      <plugin name="differential_drive_controller" filename="libdiffdrive_plugin.so">                
        <alwaysOn>true</alwaysOn>
        <update>100</update>
        <updateRate>100.0</updateRate>
        <leftJoint>left_wheel_joint</leftJoint>
        <rightJoint>right_wheel_joint</rightJoint>
        <wheelSeparation>0.508</wheelSeparation>
        <wheelDiameter>0.254</wheelDiameter> 
        <torque>3000</torque>
        <interface:position name="position_iface_0"/>
        <robotNamespace>/</robotNamespace>
        <topicName>cmd_vel</topicName>
      </plugin>
    </gazebo>
    
    <gazebo reference="base_link">
      <material>Gazebo/Grey</material>
    </gazebo>
    
    <gazebo reference="left_caster">
      <mu1>0</mu1>
      <mu2>0</mu2>
      <material>Gazebo/Black</material>
    </gazebo>
    
    <gazebo reference="right_caster">
      <mu1>0</mu1>
      <mu2>0</mu2>
      <material>Gazebo/Black</material>
    </gazebo>
    
    <gazebo reference="left_wheel">
      <mu1>1</mu1>
      <mu2>0.7</mu2>
      <material>Gazebo/Road</material>
    </gazebo>
    
    <gazebo reference="right_wheel">
      <mu1>1</mu1>
      <mu2>0.7</mu2>
      <material>Gazebo/Road</material>
    </gazebo>
</robot>
